[2022-01-31 12:12:59,101] {taskinstance.py:1032} INFO - Dependencies all met for <TaskInstance: data_ingestion_gcs_dag_test.download_dataset_task scheduled__2019-09-01T00:00:00+00:00 [queued]>
[2022-01-31 12:12:59,874] {taskinstance.py:1032} INFO - Dependencies all met for <TaskInstance: data_ingestion_gcs_dag_test.download_dataset_task scheduled__2019-09-01T00:00:00+00:00 [queued]>
[2022-01-31 12:12:59,895] {taskinstance.py:1238} INFO - 
--------------------------------------------------------------------------------
[2022-01-31 12:12:59,900] {taskinstance.py:1239} INFO - Starting attempt 1 of 2
[2022-01-31 12:12:59,909] {taskinstance.py:1240} INFO - 
--------------------------------------------------------------------------------
[2022-01-31 12:13:00,820] {taskinstance.py:1259} INFO - Executing <Task(BashOperator): download_dataset_task> on 2019-09-01 00:00:00+00:00
[2022-01-31 12:13:01,058] {standard_task_runner.py:52} INFO - Started process 10754 to run task
[2022-01-31 12:13:01,219] {standard_task_runner.py:76} INFO - Running: ['***', 'tasks', 'run', 'data_ingestion_gcs_dag_test', 'download_dataset_task', 'scheduled__2019-09-01T00:00:00+00:00', '--job-id', '233', '--raw', '--subdir', 'DAGS_FOLDER/data_ingestion_gcs_dag.py', '--cfg-path', '/tmp/tmpjxwko6wt', '--error-file', '/tmp/tmp8rqvtqrh']
[2022-01-31 12:13:01,270] {standard_task_runner.py:77} INFO - Job 233: Subtask download_dataset_task
[2022-01-31 12:13:03,547] {logging_mixin.py:109} INFO - Running <TaskInstance: data_ingestion_gcs_dag_test.download_dataset_task scheduled__2019-09-01T00:00:00+00:00 [running]> on host e72d6c5f15dc
[2022-01-31 12:13:05,969] {warnings.py:110} WARNING - /home/***/.local/lib/python3.7/site-packages/***/utils/context.py:152: AirflowContextDeprecationWarning: Accessing 'execution_date' from the template is deprecated and will be removed in a future version. Please use 'data_interval_start' or 'logical_date' instead.
  warnings.warn(_create_deprecation_warning(key, self._deprecation_replacements[key]))

[2022-01-31 12:13:06,666] {taskinstance.py:1426} INFO - Exporting the following env vars:
AIRFLOW_CTX_DAG_OWNER=***
AIRFLOW_CTX_DAG_ID=data_ingestion_gcs_dag_test
AIRFLOW_CTX_TASK_ID=download_dataset_task
AIRFLOW_CTX_EXECUTION_DATE=2019-09-01T00:00:00+00:00
AIRFLOW_CTX_DAG_RUN_ID=scheduled__2019-09-01T00:00:00+00:00
[2022-01-31 12:13:06,773] {subprocess.py:62} INFO - Tmp dir root location: 
 /tmp
[2022-01-31 12:13:06,787] {subprocess.py:74} INFO - Running command: ['bash', '-c', 'curl -sS https://s3.amazonaws.com/nyc-tlc/trip+data/yellow_tripdata_2019-09.csv > /opt/***/yellow_tripdata_2019-09.csv']
[2022-01-31 12:13:07,236] {subprocess.py:85} INFO - Output:
[2022-01-31 12:22:01,191] {subprocess.py:89} INFO - curl: (18) transfer closed with 168125480 bytes remaining to read
[2022-01-31 12:22:06,351] {subprocess.py:93} INFO - Command exited with return code 18
[2022-01-31 12:38:28,833] {taskinstance.py:1700} ERROR - Task failed with exception
Traceback (most recent call last):
  File "/home/airflow/.local/lib/python3.7/site-packages/airflow/models/taskinstance.py", line 1329, in _run_raw_task
    self._execute_task_with_callbacks(context)
  File "/home/airflow/.local/lib/python3.7/site-packages/airflow/models/taskinstance.py", line 1455, in _execute_task_with_callbacks
    result = self._execute_task(context, self.task)
  File "/home/airflow/.local/lib/python3.7/site-packages/airflow/models/taskinstance.py", line 1511, in _execute_task
    result = execute_callable(context=context)
  File "/home/airflow/.local/lib/python3.7/site-packages/airflow/operators/bash.py", line 188, in execute
    f'Bash command failed. The command returned a non-zero exit code {result.exit_code}.'
airflow.exceptions.AirflowException: Bash command failed. The command returned a non-zero exit code 18.
[2022-01-31 12:38:49,324] {taskinstance.py:1277} INFO - Marking task as UP_FOR_RETRY. dag_id=data_ingestion_gcs_dag_test, task_id=download_dataset_task, execution_date=20190901T000000, start_date=20220131T121259, end_date=20220131T123845
[2022-01-31 12:39:25,119] {standard_task_runner.py:92} ERROR - Failed to execute job 233 for task download_dataset_task
Traceback (most recent call last):
  File "/home/airflow/.local/lib/python3.7/site-packages/airflow/task/task_runner/standard_task_runner.py", line 85, in _start_by_fork
    args.func(args, dag=self.dag)
  File "/home/airflow/.local/lib/python3.7/site-packages/airflow/cli/cli_parser.py", line 48, in command
    return func(*args, **kwargs)
  File "/home/airflow/.local/lib/python3.7/site-packages/airflow/utils/cli.py", line 92, in wrapper
    return f(*args, **kwargs)
  File "/home/airflow/.local/lib/python3.7/site-packages/airflow/cli/commands/task_command.py", line 298, in task_run
    _run_task_by_selected_method(args, dag, ti)
  File "/home/airflow/.local/lib/python3.7/site-packages/airflow/cli/commands/task_command.py", line 107, in _run_task_by_selected_method
    _run_raw_task(args, ti)
  File "/home/airflow/.local/lib/python3.7/site-packages/airflow/cli/commands/task_command.py", line 184, in _run_raw_task
    error_file=args.error_file,
  File "/home/airflow/.local/lib/python3.7/site-packages/airflow/utils/session.py", line 70, in wrapper
    return func(*args, session=session, **kwargs)
  File "/home/airflow/.local/lib/python3.7/site-packages/airflow/models/taskinstance.py", line 1329, in _run_raw_task
    self._execute_task_with_callbacks(context)
  File "/home/airflow/.local/lib/python3.7/site-packages/airflow/models/taskinstance.py", line 1455, in _execute_task_with_callbacks
    result = self._execute_task(context, self.task)
  File "/home/airflow/.local/lib/python3.7/site-packages/airflow/models/taskinstance.py", line 1511, in _execute_task
    result = execute_callable(context=context)
  File "/home/airflow/.local/lib/python3.7/site-packages/airflow/operators/bash.py", line 188, in execute
    f'Bash command failed. The command returned a non-zero exit code {result.exit_code}.'
airflow.exceptions.AirflowException: Bash command failed. The command returned a non-zero exit code 18.
[2022-01-31 12:39:46,238] {local_task_job.py:154} INFO - Task exited with return code 1
[2022-01-31 12:41:19,068] {local_task_job.py:264} INFO - 0 downstream tasks scheduled from follow-on schedule check
