[2022-01-31 17:34:41,102] {taskinstance.py:1032} INFO - Dependencies all met for <TaskInstance: data_ingestion_gcs_time_zone.remove_uploaded_file manual__2022-01-31T17:27:58.079997+00:00 [queued]>
[2022-01-31 17:34:41,196] {taskinstance.py:1032} INFO - Dependencies all met for <TaskInstance: data_ingestion_gcs_time_zone.remove_uploaded_file manual__2022-01-31T17:27:58.079997+00:00 [queued]>
[2022-01-31 17:34:41,200] {taskinstance.py:1238} INFO - 
--------------------------------------------------------------------------------
[2022-01-31 17:34:41,203] {taskinstance.py:1239} INFO - Starting attempt 2 of 2
[2022-01-31 17:34:41,206] {taskinstance.py:1240} INFO - 
--------------------------------------------------------------------------------
[2022-01-31 17:34:41,355] {taskinstance.py:1259} INFO - Executing <Task(BashOperator): remove_uploaded_file> on 2022-01-31 17:27:58.079997+00:00
[2022-01-31 17:34:41,414] {standard_task_runner.py:52} INFO - Started process 796 to run task
[2022-01-31 17:34:41,449] {standard_task_runner.py:76} INFO - Running: ['***', 'tasks', 'run', 'data_ingestion_gcs_time_zone', 'remove_uploaded_file', 'manual__2022-01-31T17:27:58.079997+00:00', '--job-id', '288', '--raw', '--subdir', 'DAGS_FOLDER/data_ingestion_time_zone.py', '--cfg-path', '/tmp/tmpcnnqpwjp', '--error-file', '/tmp/tmp75m64kql']
[2022-01-31 17:34:41,454] {standard_task_runner.py:77} INFO - Job 288: Subtask remove_uploaded_file
[2022-01-31 17:34:41,803] {logging_mixin.py:109} INFO - Running <TaskInstance: data_ingestion_gcs_time_zone.remove_uploaded_file manual__2022-01-31T17:27:58.079997+00:00 [running]> on host 943e1344cac5
[2022-01-31 17:34:42,032] {taskinstance.py:1426} INFO - Exporting the following env vars:
AIRFLOW_CTX_DAG_OWNER=***
AIRFLOW_CTX_DAG_ID=data_ingestion_gcs_time_zone
AIRFLOW_CTX_TASK_ID=remove_uploaded_file
AIRFLOW_CTX_EXECUTION_DATE=2022-01-31T17:27:58.079997+00:00
AIRFLOW_CTX_DAG_RUN_ID=manual__2022-01-31T17:27:58.079997+00:00
[2022-01-31 17:34:42,042] {subprocess.py:62} INFO - Tmp dir root location: 
 /tmp
[2022-01-31 17:34:42,046] {subprocess.py:74} INFO - Running command: ['bash', '-c', 'rm /opt/***/taxi+_zone_lookup.csv /opt/***/taxi+_zone_lookup.parquet']
[2022-01-31 17:34:42,104] {subprocess.py:85} INFO - Output:
[2022-01-31 17:34:42,206] {subprocess.py:89} INFO - /bin/rm: cannot remove '/opt/***/taxi+_zone_lookup.csv': No such file or directory
[2022-01-31 17:34:42,209] {subprocess.py:89} INFO - /bin/rm: cannot remove '/opt/***/taxi+_zone_lookup.parquet': No such file or directory
[2022-01-31 17:34:42,211] {subprocess.py:93} INFO - Command exited with return code 1
[2022-01-31 17:34:42,257] {taskinstance.py:1700} ERROR - Task failed with exception
Traceback (most recent call last):
  File "/home/airflow/.local/lib/python3.7/site-packages/airflow/models/taskinstance.py", line 1329, in _run_raw_task
    self._execute_task_with_callbacks(context)
  File "/home/airflow/.local/lib/python3.7/site-packages/airflow/models/taskinstance.py", line 1455, in _execute_task_with_callbacks
    result = self._execute_task(context, self.task)
  File "/home/airflow/.local/lib/python3.7/site-packages/airflow/models/taskinstance.py", line 1511, in _execute_task
    result = execute_callable(context=context)
  File "/home/airflow/.local/lib/python3.7/site-packages/airflow/operators/bash.py", line 188, in execute
    f'Bash command failed. The command returned a non-zero exit code {result.exit_code}.'
airflow.exceptions.AirflowException: Bash command failed. The command returned a non-zero exit code 1.
[2022-01-31 17:34:42,301] {taskinstance.py:1277} INFO - Marking task as FAILED. dag_id=data_ingestion_gcs_time_zone, task_id=remove_uploaded_file, execution_date=20220131T172758, start_date=20220131T173441, end_date=20220131T173442
[2022-01-31 17:34:42,363] {standard_task_runner.py:92} ERROR - Failed to execute job 288 for task remove_uploaded_file
Traceback (most recent call last):
  File "/home/airflow/.local/lib/python3.7/site-packages/airflow/task/task_runner/standard_task_runner.py", line 85, in _start_by_fork
    args.func(args, dag=self.dag)
  File "/home/airflow/.local/lib/python3.7/site-packages/airflow/cli/cli_parser.py", line 48, in command
    return func(*args, **kwargs)
  File "/home/airflow/.local/lib/python3.7/site-packages/airflow/utils/cli.py", line 92, in wrapper
    return f(*args, **kwargs)
  File "/home/airflow/.local/lib/python3.7/site-packages/airflow/cli/commands/task_command.py", line 298, in task_run
    _run_task_by_selected_method(args, dag, ti)
  File "/home/airflow/.local/lib/python3.7/site-packages/airflow/cli/commands/task_command.py", line 107, in _run_task_by_selected_method
    _run_raw_task(args, ti)
  File "/home/airflow/.local/lib/python3.7/site-packages/airflow/cli/commands/task_command.py", line 184, in _run_raw_task
    error_file=args.error_file,
  File "/home/airflow/.local/lib/python3.7/site-packages/airflow/utils/session.py", line 70, in wrapper
    return func(*args, session=session, **kwargs)
  File "/home/airflow/.local/lib/python3.7/site-packages/airflow/models/taskinstance.py", line 1329, in _run_raw_task
    self._execute_task_with_callbacks(context)
  File "/home/airflow/.local/lib/python3.7/site-packages/airflow/models/taskinstance.py", line 1455, in _execute_task_with_callbacks
    result = self._execute_task(context, self.task)
  File "/home/airflow/.local/lib/python3.7/site-packages/airflow/models/taskinstance.py", line 1511, in _execute_task
    result = execute_callable(context=context)
  File "/home/airflow/.local/lib/python3.7/site-packages/airflow/operators/bash.py", line 188, in execute
    f'Bash command failed. The command returned a non-zero exit code {result.exit_code}.'
airflow.exceptions.AirflowException: Bash command failed. The command returned a non-zero exit code 1.
[2022-01-31 17:34:42,389] {local_task_job.py:154} INFO - Task exited with return code 1
[2022-01-31 17:34:42,508] {local_task_job.py:264} INFO - 0 downstream tasks scheduled from follow-on schedule check
